Workbook

Sheet Test Cases
A1: No. | B1: กลุ่ม (Module) | C1: Scenario | D1: ขั้นตอนการทดสอบ (Steps) | E1: ผลลัพธ์ที่คาดหวัง (Expected Result) | F1: ผลการทดสอบล่าสุด (Result) | G1: หมายเหตุ / สาเหตุที่ไม่ผ่าน (Notes) | H1: Priority
A2: 1 | B2: Login | C2: Login With Valid Credentials | D2: 1. เปิดเว็บ 2. กรอก Username/Password ถูกต้อง 3. กดเข้าสู่ระบบ | E2: เข้าสู่หน้า Dashboard สำเร็จ | F2: PASS | G2: - | H2: High
A3: 2 | B3: Login | C3: Login With Invalid Password | D3: 1. กรอก Username ถูกต้อง + Password ผิด 2. กดเข้าสู่ระบบ | E3: ระบบไม่ยอมให้เข้า และแจ้งเตือน | F3: PASS | G3: - | H3: High
A4: 3 | B4: Login | C4: Login With Invalid Username | D4: 1. กรอก Username ที่ไม่มีในระบบ + Password ใดๆ 2. กดเข้าสู่ระบบ | E4: ระบบไม่ยอมให้เข้า และแจ้งเตือน | F4: PASS | G4: - | H4: High
A5: 4 | B5: Login | C5: Login With Empty Credentials | D5: 1. ไม่กรอกข้อมูลใดๆ 2. กดเข้าสู่ระบบ | E5: ระบบไม่ยอมให้เข้า และแจ้งเตือน | F5: PASS | G5: - | H5: Medium
A6: 5 | B6: Login | C6: Login With Username Only (Empty Password) | D6: 1. กรอกเฉพาะ Username 2. กดเข้าสู่ระบบ | E6: ระบบไม่ยอมให้เข้า และแจ้งเตือน | F6: PASS | G6: - | H6: Medium
A7: 6 | B7: Login | C7: Password Field Should Mask Input | D7: 1. ตรวจสอบ attribute type ของช่อง Password | E7: ช่อง Password ต้องเป็น type="password" | F7: PASS | G7: - | H7: Medium
A8: 7 | B8: Login | C8: User Can Logout Successfully | D8: 1. Login สำเร็จ 2. กดปุ่ม Logout (title="ออกจากระบบ") | E8: กลับมาหน้า Login | F8: PASS | H8: High
A9: 8 | B9: Add Lead | C9: Execute Complete Add Lead Workflow | D9: 1. Login สำเร็จ 2. เปิด Modal เพิ่มลีดใหม่ 3. กรอกข้อมูลครบทุกช่อง 4. กดบันทึก | E9: บันทึกสำเร็จ Modal ปิดสนิท | F9: PASS | H9: High
A10: 9 | B10: Add Lead | C10: Add Lead With Missing Required Fields | D10: 1. เปิด Modal เพิ่มลีดใหม่ 2. ไม่กรอกข้อมูล 3. กดบันทึก | E10: ระบบ Block และแจ้งเตือน field required | F10: PASS | G10: - | H10: High
A11: 11 | B11: Add Lead | C11: Add Lead With Invalid Phone Format | D11: 1. เปิด Modal 2. กรอกเบอร์โทรเป็นตัวอักษร 3. กดบันทึก | E11: แจ้งเตือนหรือไม่ยอมรับข้อมูล | F11: PASS | G11: - | H11: Medium
A12: 12 | B12: Add Lead | C12: Add Lead With Duplicate Tax ID | D12: 1. เพิ่มลีดด้วยเลขนิติบุคคลหนึ่ง 2. เพิ่มลีดซ้ำด้วยเลขเดียวกัน | E12: แจ้งเตือนข้อมูลซ้ำ ไม่บันทึกซ้ำ | F12: PASS | H12: Medium
A13: 14 | B13: Add Lead | C13: Cancel Add Lead Modal Without Saving | D13: 1. เปิด Modal 2. กรอกข้อมูลบางส่วน 3. กดยกเลิก | E13: Modal ปิดสนิท ไม่มีข้อมูลถูกบันทึก | F13: PASS | H13: Medium
A14: 15 | B14: Edit Lead | C14: Edit Existing Lead Successfully | D14: 1. คลิกแก้ไขแถวแรกในตาราง 2. แก้ไขชื่อบริษัท 3. กดบันทึก | E14: บันทึกสำเร็จ ข้อมูลในตารางอัปเดต | F14: PASS | H14: High
A15: 16 | B15: Edit Lead | C15: Cancel Edit Lead Without Saving Changes | D15: 1. คลิกแก้ไขแถวแรก 2. แก้ไขข้อมูล 3. กดยกเลิก | E15: ข้อมูลเดิมไม่เปลี่ยนแปลง | F15: PASS | H15: Medium
A16: 17 | B16: Delete Lead | C16: Delete Lead With Confirmation | D16: 1. คลิกลบแถวแรก 2. กดยืนยัน | E16: ข้อมูลหายไปจากตาราง จำนวนแถวลดลง | F16: PASS | H16: High
A17: 18 | B17: Delete Lead | C17: Cancel Delete Lead Confirmation | D17: 1. คลิกลบแถวแรก 2. กดยกเลิกที่หน้า confirm | E17: ข้อมูลไม่ถูกลบ จำนวนแถวเท่าเดิม | F17: PASS | H17: Medium
A18: 19 | B18: Search | C18: Search Leads With Existing Keyword | D18: 1. พิมพ์คำค้นที่มีอยู่จริง | E18: ตารางกรองผลลัพธ์ตรงกับคำค้น | F18: PASS | H18: High
A19: 20 | B19: Search | C19: Search Leads With Non-Existing Keyword | D19: 1. พิมพ์คำค้นที่ไม่มีในระบบ | E19: แสดงข้อความ 'ไม่พบข้อมูล' | F19: PASS | G19: - | H19: Medium
A20: 21 | B20: Search | C20: Search With Special Characters / Injection Attempt | D20: 1. พิมพ์อักขระพิเศษ/SQL injection ในช่องค้นหา | E20: ระบบไม่ error ไม่มีช่องโหว่ | F20: PASS | G20: - | H20: High
A21: 22 | B21: Search | C21: Clear Search Should Restore Full List | D21: 1. ค้นหาจนตารางว่าง 2. ล้างคำค้นหา | E21: ตารางกลับมาแสดงข้อมูลทั้งหมดเหมือนเดิม (จำนวนแถวเท่าก่อนค้นหา) | F21: PASS | H21: Medium
A22: 23 | B22: Filter | C22: Filter Leads By Branch | D22: 1. เปิด Dropdown กรองสาขา (เป็น native <select>) 2. ตรวจสอบตัวเลือก | E22: Dropdown มีตัวเลือกสาขาให้เลือก | F22: PASS | H22: Medium
A23: 24 | B23: Filter | C23: Filter Combined With Search | D23: 1. เปิด Filter สาขา 2. ค้นหาพร้อมกัน | E23: ผลลัพธ์ตรงตามเงื่อนไขทั้งสอง | F23: PASS | G23: - | H23: Low
A24: 25 | B24: Sort/Pagination | C24: Sort Table By Company Name Column | D24: 1. คลิกหัวตาราง 'ชื่อบริษัท' | E24: ข้อมูลเรียงลำดับตามคอลัมน์ | F24: PASS | H24: Low
A25: 26 | B25: Sort/Pagination | C25: Navigate To Next Page | D25: 1. กดปุ่มหน้าถัดไป (ถ้ามี) | E25: เปลี่ยนหน้าสำเร็จ หรือข้ามถ้าไม่มี pagination | F25: PASS | H25: Low
A26: 27 | B26: Export | C26: Export Lead Data | D26: 1. กดปุ่ม Export | E26: ดาวน์โหลดไฟล์สำเร็จ ไม่มี error | F26: PASS | H26: Low
A27: 28 | B27: Table Display | C27: Verify Row Count Text Display | D27: 1. ตรวจสอบข้อความนับจำนวนแถวใต้ตาราง | E27: แสดงข้อความจำนวนรายการถูกต้อง | F27: PASS | H27: Low
A28: 29 | B28: Table Display | C28: Table Should Not Break With Long Company Name | D28: 1. เพิ่มลีดชื่อบริษัทยาวมาก | E28: ตารางแสดงผลได้โดยไม่พัง layout | F28: PASS | G28: - | H28: Low
A29: 30 | B29: Session/Security | C29: Direct URL Access Without Login Should Redirect | D29: 1. เข้า URL หน้า Dashboard ตรงๆ โดยไม่ Login | E29: ถูก redirect กลับหน้า Login | F29: PASS | G29: - | H29: High
A30: 31 | B30: Session/Security | C30: Refresh Page After Login Should Keep Session | D30: 1. Login สำเร็จ 2. Refresh หน้าเว็บ | E30: Session ไม่หลุด ยังอยู่หน้า Dashboard | F30: PASS | G30: - | H30: High
A31: 31 | B31: Report page | C31: Navigate To Reports Page Successfully | D31: 1. กรอก Username = Username ที่ถูกต้อง, Password = Password ที่ถูกต้อง แล้วกด Login 2. ตรวจสอบว่าระบบพาไปหน้า Dashboard สำเร็จ 3. กดเมนู "รายงานการติดตาม" ที่ Sidebar 4. ตรวจสอบว่าเข้าหน้ารายงานสำเร็จ | E31: ทดสอบเข้าหน้ารายงานการติดตามจากเมนู Sidebar | F31: PASS | H31: Medium
A32: 32 | B32: Report page | C32: Reports Page Displays Summary Cards | D32: 1. กรอก Username = Username ที่ถูกต้อง, Password = Password ที่ถูกต้อง แล้วกด Login 2. ตรวจสอบว่าระบบพาไปหน้า Dashboard สำเร็จ 3. กดเมนู "รายงานการติดตาม" ที่ Sidebar 4. ตรวจสอบว่าเข้าหน้ารายงานสำเร็จ 5. ตรวจสอบว่าตารางรายงานแสดงผล | E32: ทดสอบว่าหน้ารายงานแสดงการ์ดสรุปตัวเลข (รายการทั้งหมด/ปิด/ฯลฯ) ครบถ้วน | F32: PASS | H32: Medium
A33: 33 | B33: Report page | C33: Change Report Date Range Filter | D33: 1. กรอก Username = Username ที่ถูกต้อง, Password = Password ที่ถูกต้อง แล้วกด Login 2. ตรวจสอบว่าระบบพาไปหน้า Dashboard สำเร็จ 3. กดเมนู "รายงานการติดตาม" ที่ Sidebar 4. ตรวจสอบว่าเข้าหน้ารายงานสำเร็จ 5. กดปุ่มเลือกช่วงเวลา 6. ตรวจสอบว่าข้อความ/องค์ประกอบแสดงผล: ${REPORTS_DATE_RANGE_BTN} | E33: ทดสอบเปลี่ยนช่วงเวลาแสดงข้อมูลรายงาน (เช่น 6 เดือนล่าสุด) | F33: PASS | H33: Medium
A34: 34 | B34: Report page | C34: Export Reports Data Without Errors | D34: 1. กรอก Username = Username ที่ถูกต้อง, Password = Password ที่ถูกต้อง แล้วกด Login 2. ตรวจสอบว่าระบบพาไปหน้า Dashboard สำเร็จ 3. กดเมนู "รายงานการติดตาม" ที่ Sidebar 4. ตรวจสอบว่าเข้าหน้ารายงานสำเร็จ 5. กดปุ่ม Export Reports 6. ตรวจสอบว่าไม่พบ element ที่ระบุ: ข้อความแจ้งเตือน validation | E34: ต้องไม่เกิด error | F34: PASS | H34: Medium
A35: 35 | B35: Role | C35: Navigate To Role Management Page Successfully | D35: 1. กรอก Username = Username ที่ถูกต้อง, Password = Password ที่ถูกต้อง แล้วกด Login 2. ตรวจสอบว่าระบบพาไปหน้า Dashboard สำเร็จ 3. กดเมนู "จัดการ Role" ที่ Sidebar 4. ตรวจสอบว่าเข้าหน้าจัดการ Role สำเร็จ | E35: ทดสอบเข้าหน้าจัดการ Role จากเมนู Sidebar | F35: PASS | H35: Medium
A36: 36 | B36: Role | C36: Role Management Displays Existing Role List | D36: 1. กรอก Username = Username ที่ถูกต้อง, Password = Password ที่ถูกต้อง แล้วกด Login 2. ตรวจสอบว่าระบบพาไปหน้า Dashboard สำเร็จ 3. กดเมนู "จัดการ Role" ที่ Sidebar 4. ตรวจสอบว่าเข้าหน้าจัดการ Role สำเร็จ 5. ตรวจสอบว่าพบข้อความที่ระบุ: "superadmin" | E36: มี list ตาม role ที่มี | F36: PASS | H36: Medium
A37: 37 | B37: Role | C37: Create New Role Button Should Open Form | D37: 1. กรอก Username = Username ที่ถูกต้อง, Password = Password ที่ถูกต้อง แล้วกด Login 2. ตรวจสอบว่าระบบพาไปหน้า Dashboard สำเร็จ 3. กดเมนู "จัดการ Role" ที่ Sidebar 4. ตรวจสอบว่าเข้าหน้าจัดการ Role สำเร็จ 5. กดปุ่ม "สร้าง Role ใหม่" 6. ตรวจสอบว่าพบข้อความที่ระบุ: "Role" | E37: ต้องเปิดฟอร์ม/Modal สร้าง Role | F37: PASS | H37: Medium
A38: 38 | B38: Role | C38: Edit Existing Role Opens Edit Form | D38: 1. กรอก Username = Username ที่ถูกต้อง, Password = Password ที่ถูกต้อง แล้วกด Login 2. ตรวจสอบว่าระบบพาไปหน้า Dashboard สำเร็จ 3. กดเมนู "จัดการ Role" ที่ Sidebar 4. ตรวจสอบว่าเข้าหน้าจัดการ Role สำเร็จ 5. กดปุ่มแก้ไขที่แถวแรกของตาราง Role 6. ตรวจสอบว่าพบข้อความที่ระบุ: "แก้ไข" | E38: ต้องเปิดฟอร์มแก้ไขข้อมูล Role นั้น | F38: PASS | H38: Medium
A39: 39 | B39: Role | C39: หน้าจัดการ Permission | D39: ใส่ชื่อrole ซ้ำกับ role ที่มีเเล้วกดบันทึก | E39: ควรขึ้นข้อความ Error | F39: PASS | H39: Medium
A40: 41 | B40: Role | C40: สิทธิ์การเข้าถึง (Authorization) | D40: 1. Login ด้วย user สิทธิ์ต่ำ 2. ตรวจสอบตารางข้อมูลลีดแถวแรก | E40: ทดสอบว่า user สิทธิ์ต่ำต้องไม่เห็นปุ่มลบข้อมูลลีด (ถ้าระบบจำกัดสิทธิ์ตาม role) | F40: PASS | H40: Low
...

Sheet Summary
A1: สรุปผลการทดสอบ Sales_CRM (31 Scenarios)
A3: จำนวน Test Case ทั้งหมด | B3: =COUNTA('Test Cases'!A2:A30) -> 29
A4: ผ่าน (PASS) | B4: =COUNTIF('Test Cases'!F2:F30,"PASS") -> 29
A5: ไม่ผ่าน (FAIL) | B5: =COUNTIF('Test Cases'!F2:F30,"FAIL") -> 0
A6: อัตราผ่าน (%) | B6: =B4/B3*100 -> 100
A8: สรุปตามกลุ่ม (Module)
A9: Module | B9: PASS | C9: FAIL
A10: Login | B10: =COUNTIFS('Test Cases'!B2:B30,A10,'Test Cases'!F2:F30,"PASS") -> 7 | C10: =COUNTIFS('Test Cases'!B2:B30,A10,'Test Cases'!F2:F30,"FAIL") -> 0
A11: Add Lead | B11: =COUNTIFS('Test Cases'!B2:B30,A11,'Test Cases'!F2:F30,"PASS") -> 5 | C11: =COUNTIFS('Test Cases'!B2:B30,A11,'Test Cases'!F2:F30,"FAIL") -> 0
A12: Edit Lead | B12: =COUNTIFS('Test Cases'!B2:B30,A12,'Test Cases'!F2:F30,"PASS") -> 2 | C12: =COUNTIFS('Test Cases'!B2:B30,A12,'Test Cases'!F2:F30,"FAIL") -> 0
A13: Delete Lead | B13: =COUNTIFS('Test Cases'!B2:B30,A13,'Test Cases'!F2:F30,"PASS") -> 2 | C13: =COUNTIFS('Test Cases'!B2:B30,A13,'Test Cases'!F2:F30,"FAIL") -> 0
A14: Search | B14: =COUNTIFS('Test Cases'!B2:B30,A14,'Test Cases'!F2:F30,"PASS") -> 4 | C14: =COUNTIFS('Test Cases'!B2:B30,A14,'Test Cases'!F2:F30,"FAIL") -> 0
A15: Filter | B15: =COUNTIFS('Test Cases'!B2:B30,A15,'Test Cases'!F2:F30,"PASS") -> 2 | C15: =COUNTIFS('Test Cases'!B2:B30,A15,'Test Cases'!F2:F30,"FAIL") -> 0
A16: Sort/Pagination | B16: =COUNTIFS('Test Cases'!B2:B30,A16,'Test Cases'!F2:F30,"PASS") -> 2 | C16: =COUNTIFS('Test Cases'!B2:B30,A16,'Test Cases'!F2:F30,"FAIL") -> 0
A17: Export | B17: =COUNTIFS('Test Cases'!B2:B30,A17,'Test Cases'!F2:F30,"PASS") -> 1 | C17: =COUNTIFS('Test Cases'!B2:B30,A17,'Test Cases'!F2:F30,"FAIL") -> 0
A18: Table Display | B18: =COUNTIFS('Test Cases'!B2:B30,A18,'Test Cases'!F2:F30,"PASS") -> 2 | C18: =COUNTIFS('Test Cases'!B2:B30,A18,'Test Cases'!F2:F30,"FAIL") -> 0
A19: Session/Security | B19: =COUNTIFS('Test Cases'!B2:B30,A19,'Test Cases'!F2:F30,"PASS") -> 2 | C19: =COUNTIFS('Test Cases'!B2:B30,A19,'Test Cases'!F2:F30,"FAIL") -> 0
